---
title: 异常
tags: []
categories:
  - [未分类]
date: 2023-04-04T00:49:29.000Z
updated: 2024-10-14T13:56:23.333Z
comments: false

---

<!--more-->
# 异常

​	

## try和catch

```c++
try
{
    ····;
}
catch(typename1 & tyn1)
{
    ····;
}
catch(typename2 & tyn2)
{
    ····;
}
catch(typename3 & tyn3)
{
    ····;
}
....;
catch(...) //省略号代表即使不知道的异常类型也能捕捉
{
    ····;
}
```

## 异常类型

### 定义异常类型

```C++
class bad1
{
    private:
    ····;
    public:
    ····;
}
```

### 抛出异常throw

```c++
double A(int a, int b)
{
 	if(a!=b)
        bad1 b();
        throw b; //或者throw bad1();throw的东西必须是个对象，bad1()隐式的的创建了一个对象
    return 1.0;
}
```

**throw会立刻终止执行下面的程序，并执行栈解退，将控制权向上传递，并且上一个函数如果有catch则会捕获这一异常。特别的是栈解退的如果是类对象将会为该对象调用析构函数。**

### 捕获异常catch

```c++
catch(bad1 & b1)
{
    cout << "····异常";
}
```

**注意**b1指向的是的是b的**拷贝副本**并不是指向b本身。

## 基类和异常类的捕捉顺序

当使用catch来捕获基类的异常类型，这时如果有抛出派生类型的错误，catch也将会捕获。

```c++
//bad.h
class bad1
{
    .....;
}
class bad2 : public bad1
{
    .....;
}
class bad3 : public bad2
{
    ....;
}
```

```C++
#include "bad.h"
void bad(int a, int b);
int main()
{
    int a, b;
    
    
    //捕捉异常
    try
    {
        bad(a, b);
    }
    catch(bad3) //如果第一个捕捉的异常是基类那他将捕捉由他派生的所有类，所以异常的捕获顺序是倒序。
    {
        ...;
    }
    catch(bad2)
    {
        ....;
    }
    catch(bad1)
    {
        ....;
    }
    
    return0;
}

void bad(int a, int b)
{
    if(a = b)
    {
        throw bad1();
    }
    if(a < b)
    {
        thorw bad2();
    }
    if(a > b)
    {
        throw bad3();
    }
}
```

## exception类

异常的基类

`#include<exception>` 

## stdexcept类

该类含有`logic_error`和`runtime_error`

logic_error表明存在可以通过编程修复的问题

runtime_error表明存在无法避免的问题

**stdexcept是由exception类派生的，捕捉异常时主义注意派生和基类的顺序**

## bad_alloc和new

使用new导致的内存分配问题，C++的最新处理方式是让new引发bad_alloc异常。头文件new包含bad_alloc类的声明，他也是从exception类公有派生的。

## 空指针和new

```c++
int * pi = new(std::nothrow) int;
int * pa = new(std::nowthrow) int[500];
```

`std::nothrow`和`std::nowthrow`是一个标记（开关），可以在new失败时返回一个空指针。

##  注意事项

异常和动态分配并不是能很好的配合

```c++
void test1(int n)
{
    string mesg("awdawdaw");
    ....;
    if(oh_no)
        throw exception();
    ....;
    retun;
}
```

当程序执行到thorw时程序会终止，然而程序还是会调用string的析构函数，应为程序执行了栈解退。

**但是**

```c++
void test1(int n)
{
    double * ar = new double[10];
    ....;
    if(oh_no)
        throw exception();
    ....;
    delete [] ar;
    retun;
}
```

当程序执行到throw时程序终止，delete语句不被执行这时指针还将会在内存中造成内存泄露。

**这种情况可以避免**

```c++
void test1(int n)
{
    double * ar = new double[10];
    ....;
    try
    {if(oh_no)
        throw exception();
    }
    catch(expetion &ex)
    {
        delete [] ar;
        throw; //将该次错误再次抛出到外面的函数中
    }
    retun;
}
```